Workbook

Sheet Transactions
A1: PETTY CASH BOOK
A2: Month / Year: | E2: 46113 | I2: Project: | K2: Discovery Dunes
A3: TOTAL CASH-IN (AED) | E3: TOTAL ADVANCED (AED) | I3: TOTAL RETURNED (AED) | M3: CLOSING BALANCE (AED)
A4: =E5+SUM(C8:C3006) -> 13656.81 | E4: =SUM(H8:H3006) -> 9187 | I4: =SUM(N8:N3006) -> 3900 | M4: =E5+SUM(C8:C3006)-SUM(H8:H3006)+SUM(N8:N3006)-SUM(R8:R3006) -> 8269.81
A5: Opening Balance (Cash in Hand): | E5: 5524 | I5: ← Update this when opening balance changes
A6: CASH-IN | D6: VOUCHER / ADVANCE / EXPENSE / SETTLEMENT
A7: Date | B7: Description / Ref | C7: Cash-In Amt | D7: Ref. No. | E7: Voucher Date | F7: Payee / Worker | G7: Purpose | H7: Adv. Amount | I7: Fuel | J7: Service / Labour | K7: Materials | L7: Food Allowance | M7: Others | N7: Balance Returned | O7: Actual Expense | P7: Variance (Adv−Exp) | Q7: Reimb. Amount | R7: Reimb. Paid | S7: Change Due Back
A8: 46114 | B8: Balance c/d | C8: 2132.81 | D8: V-001 | E8: 46041 | F8: Rey | G8: Advance | H8: 410 | N8: 0 | O8: =IF(G8="Reimbursement ","",I8+J8+K8+L8+M8) -> 0 | P8: =IF(G8="Reimbursement ","",H8-O8) -> 410 | S8: =IF(OR(R8="",Q8=""),0,IF(R8>Q8,R8-Q8,0)) -> 0
A9: 46114 | B9: Received from HO | C9: 5000 | D9: V-002 | E9: 46042 | F9: Ben | G9: Advance | H9: 18 | N9: 0 | O9: =IF(G9="Reimbursement ","",I9+J9+K9+L9+M9) -> 0 | P9: =IF(G9="Reimbursement ","",H9-O9) -> 18 | S9: =IF(OR(R9="",Q9=""),0,IF(R9>Q9,R9-Q9,0)) -> 0
C10: 1000 | D10: V-003 | E10: 46109 | F10: Cal | G10: Balance | H10: 2 | N10: 0 | O10: =IF(G10="Reimbursement ","",I10+J10+K10+L10+M10) -> 0 | P10: =IF(G10="Reimbursement ","",H10-O10) -> 2 | S10: =IF(OR(R10="",Q10=""),0,IF(R10>Q10,R10-Q10,0)) -> 0
D11: V-004 | E11: 46107 | F11: Dan | G11: Balance | H11: 10 | N11: 0 | O11: =IF(G11="Reimbursement ","",I11+J11+K11+L11+M11) -> 0 | P11: =IF(G11="Reimbursement ","",H11-O11) -> 10 | S11: =IF(OR(R11="",Q11=""),0,IF(R11>Q11,R11-Q11,0)) -> 0
D12: V-005 | E12: 46082 | F12: Eli | G12: Advance | H12: 500 | N12: 0 | O12: =IF(G12="Reimbursement ","",I12+J12+K12+L12+M12) -> 0 | P12: =IF(G12="Reimbursement ","",H12-O12) -> 500 | S12: =IF(OR(R12="",Q12=""),0,IF(R12>Q12,R12-Q12,0)) -> 0
D13: V-006 | E13: 46083 | F13: Ian | G13: Advance | H13: 500 | N13: 0 | O13: =IF(G13="Reimbursement ","",I13+J13+K13+L13+M13) -> 0 | P13: =IF(G13="Reimbursement ","",H13-O13) -> 500 | S13: =IF(OR(R13="",Q13=""),0,IF(R13>Q13,R13-Q13,0)) -> 0
D14: V-007 | E14: 46084 | F14: Jay | G14: Advance | H14: 1000 | N14: 0 | O14: =IF(G14="Reimbursement ","",I14+J14+K14+L14+M14) -> 0 | P14: =IF(G14="Reimbursement ","",H14-O14) -> 1000 | S14: =IF(OR(R14="",Q14=""),0,IF(R14>Q14,R14-Q14,0)) -> 0
D15: V-008 | E15: 46085 | F15: Kai | G15: Returned | N15: 200 | O15: =IF(G15="Reimbursement ","",I15+J15+K15+L15+M15) -> 0 | P15: =IF(G15="Reimbursement ","",H15-O15) -> 0 | S15: =IF(OR(R15="",Q15=""),0,IF(R15>Q15,R15-Q15,0)) -> 0
D16: V-009 | E16: 46086 | F16: Leo | G16: Advance | H16: 1000 | N16: 500 | O16: =IF(G16="Reimbursement ","",I16+J16+K16+L16+M16) -> 0 | P16: =IF(G16="Reimbursement ","",H16-O16) -> 1000 | S16: =IF(OR(R16="",Q16=""),0,IF(R16>Q16,R16-Q16,0)) -> 0
D17: V-010 | E17: 46087 | F17: Max | G17: Returned | N17: 300 | O17: =IF(G17="Reimbursement ","",I17+J17+K17+L17+M17) -> 0 | P17: =IF(G17="Reimbursement ","",H17-O17) -> 0 | S17: =IF(OR(R17="",Q17=""),0,IF(R17>Q17,R17-Q17,0)) -> 0
D18: V-011 | E18: 46088 | F18: Neo | G18: Reimbursement | N18: 0 | O18: =IF(G18="Reimbursement ","",I18+J18+K18+L18+M18) | P18: =IF(G18="Reimbursement ","",H18-O18) | Q18: 600 | S18: =IF(OR(R18="",Q18=""),0,IF(R18>Q18,R18-Q18,0)) -> 0
D19: V-012 | E19: 46089 | F19: Oli | G19: Advance | H19: 1000 | N19: 0 | O19: =IF(G19="Reimbursement ","",I19+J19+K19+L19+M19) -> 0 | P19: =IF(G19="Reimbursement ","",H19-O19) -> 1000 | S19: =IF(OR(R19="",Q19=""),0,IF(R19>Q19,R19-Q19,0)) -> 0
D20: V-013 | E20: 46090 | F20: Ray | G20: Returned | H20: 1000 | J20: 100 | N20: 400 | O20: =IF(G20="Reimbursement ","",I20+J20+K20+L20+M20) -> 100 | P20: =IF(G20="Reimbursement ","",H20-O20) -> 900 | S20: =IF(OR(R20="",Q20=""),0,IF(R20>Q20,R20-Q20,0)) -> 0
D21: V-014 | E21: 46091 | F21: Sam | G21: Advance | H21: 1500 | I21: 300 | N21: 1000 | O21: =IF(G21="Reimbursement ","",I21+J21+K21+L21+M21) -> 300 | P21: =IF(G21="Reimbursement ","",H21-O21) -> 1200 | S21: =IF(OR(R21="",Q21=""),0,IF(R21>Q21,R21-Q21,0)) -> 0
D22: V-015 | E22: 46092 | F22: Tom | G22: Reimbursement | N22: 0 | O22: =IF(G22="Reimbursement ","",I22+J22+K22+L22+M22) | P22: =IF(G22="Reimbursement ","",H22-O22) | Q22: 2000 | S22: =IF(OR(R22="",Q22=""),0,IF(R22>Q22,R22-Q22,0)) -> 0
D23: V-016 | E23: 46093 | F23: Vic | G23: Advance | H23: 500 | N23: 0 | O23: =IF(G23="Reimbursement ","",I23+J23+K23+L23+M23) -> 0 | P23: =IF(G23="Reimbursement ","",H23-O23) -> 500 | S23: =IF(OR(R23="",Q23=""),0,IF(R23>Q23,R23-Q23,0)) -> 0
D24: V-017 | E24: 46094 | F24: Zac | G24: Advance | H24: 122 | N24: 0 | O24: =IF(G24="Reimbursement ","",I24+J24+K24+L24+M24) -> 0 | P24: =IF(G24="Reimbursement ","",H24-O24) -> 122 | S24: =IF(OR(R24="",Q24=""),0,IF(R24>Q24,R24-Q24,0)) -> 0
D25: V-017 | E25: 46094 | F25: Roy | G25: Advance | H25: 123 | O25: =IF(G25="Reimbursement ","",I25+J25+K25+L25+M25) -> 0 | P25: =IF(G25="Reimbursement ","",H25-O25) -> 123 | S25: =IF(OR(R25="",Q25=""),0,IF(R25>Q25,R25-Q25,0)) -> 0
D26: V-018 | E26: 46095 | F26: Asa | G26: Advance | H26: 124 | O26: =IF(G26="Reimbursement ","",I26+J26+K26+L26+M26) -> 0 | P26: =IF(G26="Reimbursement ","",H26-O26) -> 124 | S26: =IF(OR(R26="",Q26=""),0,IF(R26>Q26,R26-Q26,0)) -> 0
D27: V-019 | E27: 46096 | F27: Gil | G27: Advance | H27: 125 | O27: =IF(G27="Reimbursement ","",I27+J27+K27+L27+M27) -> 0 | P27: =IF(G27="Reimbursement ","",H27-O27) -> 125 | S27: =IF(OR(R27="",Q27=""),0,IF(R27>Q27,R27-Q27,0)) -> 0
D28: V-020 | E28: 46097 | F28: Joe | G28: Advance | H28: 126 | N28: 0 | O28: =IF(G28="Reimbursement ","",I28+J28+K28+L28+M28) -> 0 | P28: =IF(G28="Reimbursement ","",H28-O28) -> 126 | S28: =IF(OR(R28="",Q28=""),0,IF(R28>Q28,R28-Q28,0)) -> 0
D29: V-021 | E29: 46098 | F29: Ken | G29: Advance | H29: 127 | O29: =IF(G29="Reimbursement ","",I29+J29+K29+L29+M29) -> 0 | P29: =IF(G29="Reimbursement ","",H29-O29) -> 127 | S29: =IF(OR(R29="",Q29=""),0,IF(R29>Q29,R29-Q29,0)) -> 0
D30: V-022 | E30: 46099 | F30: Lou | G30: Advance | H30: 1000 | I30: 100 | J30: 100 | K30: 100 | N30: 1000 | O30: =IF(G30="Reimbursement ","",I30+J30+K30+L30+M30) -> 300 | P30: =IF(G30="Reimbursement ","",H30-O30) -> 700 | S30: =IF(OR(R30="",Q30=""),0,IF(R30>Q30,R30-Q30,0)) -> 0
D31: V-023 | E31: 46100 | F31: Rex | G31: Reimbursement | I31: 10 | J31: 20 | K31: 30 | L31: 15 | M31: 40 | N31: 500 | O31: =IF(G31="Reimbursement ","",I31+J31+K31+L31+M31) | P31: =IF(G31="Reimbursement ","",H31-O31) | Q31: 1000 | R31: 100 | S31: =IF(OR(R31="",Q31=""),0,IF(R31>Q31,R31-Q31,0)) -> 0
O32: =IF(G32="Reimbursement ","",I32+J32+K32+L32+M32) -> 0 | P32: =IF(G32="Reimbursement ","",H32-O32) -> 0 | S32: =IF(OR(R32="",Q32=""),0,IF(R32>Q32,R32-Q32,0)) -> 0
O33: =IF(G33="Reimbursement ","",I33+J33+K33+L33+M33) -> 0 | P33: =IF(G33="Reimbursement ","",H33-O33) -> 0 | S33: =IF(OR(R33="",Q33=""),0,IF(R33>Q33,R33-Q33,0)) -> 0
O34: =IF(G34="Reimbursement ","",I34+J34+K34+L34+M34) -> 0 | P34: =IF(G34="Reimbursement ","",H34-O34) -> 0 | S34: =IF(OR(R34="",Q34=""),0,IF(R34>Q34,R34-Q34,0)) -> 0
O35: =IF(G35="Reimbursement ","",I35+J35+K35+L35+M35) -> 0 | P35: =IF(G35="Reimbursement ","",H35-O35) -> 0 | S35: =IF(OR(R35="",Q35=""),0,IF(R35>Q35,R35-Q35,0)) -> 0
O36: =IF(G36="Reimbursement ","",I36+J36+K36+L36+M36) -> 0 | P36: =IF(G36="Reimbursement ","",H36-O36) -> 0 | S36: =IF(OR(R36="",Q36=""),0,IF(R36>Q36,R36-Q36,0)) -> 0
O37: =IF(G37="Reimbursement ","",I37+J37+K37+L37+M37) -> 0 | P37: =IF(G37="Reimbursement ","",H37-O37) -> 0 | S37: =IF(OR(R37="",Q37=""),0,IF(R37>Q37,R37-Q37,0)) -> 0
O38: =IF(G38="Reimbursement ","",I38+J38+K38+L38+M38) -> 0 | P38: =IF(G38="Reimbursement ","",H38-O38) -> 0 | S38: =IF(OR(R38="",Q38=""),0,IF(R38>Q38,R38-Q38,0)) -> 0
O39: =IF(G39="Reimbursement ","",I39+J39+K39+L39+M39) -> 0 | P39: =IF(G39="Reimbursement ","",H39-O39) -> 0 | S39: =IF(OR(R39="",Q39=""),0,IF(R39>Q39,R39-Q39,0)) -> 0
O40: =IF(G40="Reimbursement ","",I40+J40+K40+L40+M40) -> 0 | P40: =IF(G40="Reimbursement ","",H40-O40) -> 0 | S40: =IF(OR(R40="",Q40=""),0,IF(R40>Q40,R40-Q40,0)) -> 0
...

Sheet Advances Summary
A1: OUTSTANDING ADVANCES — SITE SUMMARY
A2: Auto-updates from 'Transactions' sheet | D2: Month: | F2: Today's Date: | G2: =TODAY() -> 46156
A3: TOTAL ADVANCED (H) | C3: TOTAL ACCOUNTED | E3: REIMB PAID (R) | G3: NET OUTSTANDING
A4: =SUM(C16:C3015) -> 9187 | C4: =SUM(D16:D3015) -> 3900 | E4: =SUM(F16:F3015) -> 100 | G4: =SUM(G16:G3015) -> 1087
A5: STATUS: OUTSTANDING = X owes company | SETTLED = fully accounted, zero balance | OWES = company owes X (bills not fully paid) | OVERPAID = company already paid X more than owed
A6: ● OUTSTANDING | C6: ● SETTLED | E6: ● OWES | G6: ● OVERPAID
A8: HOW IT WORKS: Net = (Advanced + Reimb Paid) − (Cash Returned + Actual Expense + Bills Submitted) Example: Advance 500 → spend 200 → submit 500 bill → pay 200 (offset 300 debt) → Settled
A10: WORKER | C10: FINANCIAL BREAKDOWN | G10: NET RESULT
A11: # | B11: Worker / Payee | C11: Total Advanced | D11: Total Accounted | E11: Actual Expense | F11: Reimb Paid | G11: Net Outstanding | H11: Status
A13: TOTALS | C13: =SUM(C16:C3015) -> 9187 | D13: =SUM(D16:D3015) -> 3900 | E13: =SUM(E16:E3015) -> 700 | F13: =SUM(F16:F3015) -> 100 | G13: =SUM(G16:G3015) -> 1087 | H13: =SUM(H16:H3015) -> 0
A16: 1 | B16: {=IFERROR(IF(INDEX(Transactions!$F$8:$F$3006,MATCH(0,COUNTIF($B$11:B15,Transactions!$F$8:$F$3006),0))="","",INDEX(Transactions!$F$8:$F$3006,MATCH(0,COUNTIF($B$11:B15,Transactions!$F$8:$F$3006),0))),"")} -> Rey | C16: =IF(B16="","",SUMIF(Transactions!$F$8:$F$3006,B16,Transactions!$H$8:$H$3006)) -> 410 | D16: =IF(B16="","",SUMIF(Transactions!$F$8:$F$3006,B16,Transactions!$N$8:$N$3006)) -> 0 | E16: =IF(B16="","",SUMIF(Transactions!$F$8:$F$3006,B16,Transactions!$O$8:$O$3006)) -> 0 | F16: =IF(B16="","",SUMIF(Transactions!$F$8:$F$3006,B16,Transactions!$R$8:$R$3006)) -> 0 | G16: =IF(B16="","",(C16+F16)-(D16+E16+SUMIF(Transactions!$F$8:$F$3006,B16,Transactions!$Q$8:$Q$3006))) -> 410 | H16: =IF(B16="","",IF(G16>0,"OUTSTANDING",IF(G16=0,"SETTLED",IF(SUMIF(Transactions!$F$8:$F$3006,B16,Transactions!$Q$8:$Q$3006)>SUMIF(Transactions!$F$8:$F$3006,B16,Transactions!$R$8:$R$3006),"OWES","OVERPAID")))) -> OUTSTANDING
A17: 2 | B17: {=IFERROR(IF(INDEX(Transactions!$F$8:$F$3006,MATCH(0,COUNTIF($B$11:B16,Transactions!$F$8:$F$3006),0))="","",INDEX(Transactions!$F$8:$F$3006,MATCH(0,COUNTIF($B$11:B16,Transactions!$F$8:$F$3006),0))),"")} -> Ben | C17: =IF(B17="","",SUMIF(Transactions!$F$8:$F$3006,B17,Transactions!$H$8:$H$3006)) -> 18 | D17: =IF(B17="","",SUMIF(Transactions!$F$8:$F$3006,B17,Transactions!$N$8:$N$3006)) -> 0 | E17: =IF(B17="","",SUMIF(Transactions!$F$8:$F$3006,B17,Transactions!$O$8:$O$3006)) -> 0 | F17: =IF(B17="","",SUMIF(Transactions!$F$8:$F$3006,B17,Transactions!$R$8:$R$3006)) -> 0 | G17: =IF(B17="","",(C17+F17)-(D17+E17+SUMIF(Transactions!$F$8:$F$3006,B17,Transactions!$Q$8:$Q$3006))) -> 18 | H17: =IF(B17="","",IF(G17>0,"OUTSTANDING",IF(G17=0,"SETTLED",IF(SUMIF(Transactions!$F$8:$F$3006,B17,Transactions!$Q$8:$Q$3006)>SUMIF(Transactions!$F$8:$F$3006,B17,Transactions!$R$8:$R$3006),"OWES","OVERPAID")))) -> OUTSTANDING
A18: 3 | B18: {=IFERROR(IF(INDEX(Transactions!$F$8:$F$3006,MATCH(0,COUNTIF($B$11:B17,Transactions!$F$8:$F$3006),0))="","",INDEX(Transactions!$F$8:$F$3006,MATCH(0,COUNTIF($B$11:B17,Transactions!$F$8:$F$3006),0))),"")} -> Cal | C18: =IF(B18="","",SUMIF(Transactions!$F$8:$F$3006,B18,Transactions!$H$8:$H$3006)) -> 2 | D18: =IF(B18="","",SUMIF(Transactions!$F$8:$F$3006,B18,Transactions!$N$8:$N$3006)) -> 0 | E18: =IF(B18="","",SUMIF(Transactions!$F$8:$F$3006,B18,Transactions!$O$8:$O$3006)) -> 0 | F18: =IF(B18="","",SUMIF(Transactions!$F$8:$F$3006,B18,Transactions!$R$8:$R$3006)) -> 0 | G18: =IF(B18="","",(C18+F18)-(D18+E18+SUMIF(Transactions!$F$8:$F$3006,B18,Transactions!$Q$8:$Q$3006))) -> 2 | H18: =IF(B18="","",IF(G18>0,"OUTSTANDING",IF(G18=0,"SETTLED",IF(SUMIF(Transactions!$F$8:$F$3006,B18,Transactions!$Q$8:$Q$3006)>SUMIF(Transactions!$F$8:$F$3006,B18,Transactions!$R$8:$R$3006),"OWES","OVERPAID")))) -> OUTSTANDING
A19: 4 | B19: {=IFERROR(IF(INDEX(Transactions!$F$8:$F$3006,MATCH(0,COUNTIF($B$11:B18,Transactions!$F$8:$F$3006),0))="","",INDEX(Transactions!$F$8:$F$3006,MATCH(0,COUNTIF($B$11:B18,Transactions!$F$8:$F$3006),0))),"")} -> Dan | C19: =IF(B19="","",SUMIF(Transactions!$F$8:$F$3006,B19,Transactions!$H$8:$H$3006)) -> 10 | D19: =IF(B19="","",SUMIF(Transactions!$F$8:$F$3006,B19,Transactions!$N$8:$N$3006)) -> 0 | E19: =IF(B19="","",SUMIF(Transactions!$F$8:$F$3006,B19,Transactions!$O$8:$O$3006)) -> 0 | F19: =IF(B19="","",SUMIF(Transactions!$F$8:$F$3006,B19,Transactions!$R$8:$R$3006)) -> 0 | G19: =IF(B19="","",(C19+F19)-(D19+E19+SUMIF(Transactions!$F$8:$F$3006,B19,Transactions!$Q$8:$Q$3006))) -> 10 | H19: =IF(B19="","",IF(G19>0,"OUTSTANDING",IF(G19=0,"SETTLED",IF(SUMIF(Transactions!$F$8:$F$3006,B19,Transactions!$Q$8:$Q$3006)>SUMIF(Transactions!$F$8:$F$3006,B19,Transactions!$R$8:$R$3006),"OWES","OVERPAID")))) -> OUTSTANDING
A20: 5 | B20: {=IFERROR(IF(INDEX(Transactions!$F$8:$F$3006,MATCH(0,COUNTIF($B$11:B19,Transactions!$F$8:$F$3006),0))="","",INDEX(Transactions!$F$8:$F$3006,MATCH(0,COUNTIF($B$11:B19,Transactions!$F$8:$F$3006),0))),"")} -> Eli | C20: =IF(B20="","",SUMIF(Transactions!$F$8:$F$3006,B20,Transactions!$H$8:$H$3006)) -> 500 | D20: =IF(B20="","",SUMIF(Transactions!$F$8:$F$3006,B20,Transactions!$N$8:$N$3006)) -> 0 | E20: =IF(B20="","",SUMIF(Transactions!$F$8:$F$3006,B20,Transactions!$O$8:$O$3006)) -> 0 | F20: =IF(B20="","",SUMIF(Transactions!$F$8:$F$3006,B20,Transactions!$R$8:$R$3006)) -> 0 | G20: =IF(B20="","",(C20+F20)-(D20+E20+SUMIF(Transactions!$F$8:$F$3006,B20,Transactions!$Q$8:$Q$3006))) -> 500 | H20: =IF(B20="","",IF(G20>0,"OUTSTANDING",IF(G20=0,"SETTLED",IF(SUMIF(Transactions!$F$8:$F$3006,B20,Transactions!$Q$8:$Q$3006)>SUMIF(Transactions!$F$8:$F$3006,B20,Transactions!$R$8:$R$3006),"OWES","OVERPAID")))) -> OUTSTANDING
A21: 6 | B21: {=IFERROR(IF(INDEX(Transactions!$F$8:$F$3006,MATCH(0,COUNTIF($B$11:B20,Transactions!$F$8:$F$3006),0))="","",INDEX(Transactions!$F$8:$F$3006,MATCH(0,COUNTIF($B$11:B20,Transactions!$F$8:$F$3006),0))),"")} -> Ian | C21: =IF(B21="","",SUMIF(Transactions!$F$8:$F$3006,B21,Transactions!$H$8:$H$3006)) -> 500 | D21: =IF(B21="","",SUMIF(Transactions!$F$8:$F$3006,B21,Transactions!$N$8:$N$3006)) -> 0 | E21: =IF(B21="","",SUMIF(Transactions!$F$8:$F$3006,B21,Transactions!$O$8:$O$3006)) -> 0 | F21: =IF(B21="","",SUMIF(Transactions!$F$8:$F$3006,B21,Transactions!$R$8:$R$3006)) -> 0 | G21: =IF(B21="","",(C21+F21)-(D21+E21+SUMIF(Transactions!$F$8:$F$3006,B21,Transactions!$Q$8:$Q$3006))) -> 500 | H21: =IF(B21="","",IF(G21>0,"OUTSTANDING",IF(G21=0,"SETTLED",IF(SUMIF(Transactions!$F$8:$F$3006,B21,Transactions!$Q$8:$Q$3006)>SUMIF(Transactions!$F$8:$F$3006,B21,Transactions!$R$8:$R$3006),"OWES","OVERPAID")))) -> OUTSTANDING
A22: 7 | B22: {=IFERROR(IF(INDEX(Transactions!$F$8:$F$3006,MATCH(0,COUNTIF($B$11:B21,Transactions!$F$8:$F$3006),0))="","",INDEX(Transactions!$F$8:$F$3006,MATCH(0,COUNTIF($B$11:B21,Transactions!$F$8:$F$3006),0))),"")} -> Jay | C22: =IF(B22="","",SUMIF(Transactions!$F$8:$F$3006,B22,Transactions!$H$8:$H$3006)) -> 1000 | D22: =IF(B22="","",SUMIF(Transactions!$F$8:$F$3006,B22,Transactions!$N$8:$N$3006)) -> 0 | E22: =IF(B22="","",SUMIF(Transactions!$F$8:$F$3006,B22,Transactions!$O$8:$O$3006)) -> 0 | F22: =IF(B22="","",SUMIF(Transactions!$F$8:$F$3006,B22,Transactions!$R$8:$R$3006)) -> 0 | G22: =IF(B22="","",(C22+F22)-(D22+E22+SUMIF(Transactions!$F$8:$F$3006,B22,Transactions!$Q$8:$Q$3006))) -> 1000 | H22: =IF(B22="","",IF(G22>0,"OUTSTANDING",IF(G22=0,"SETTLED",IF(SUMIF(Transactions!$F$8:$F$3006,B22,Transactions!$Q$8:$Q$3006)>SUMIF(Transactions!$F$8:$F$3006,B22,Transactions!$R$8:$R$3006),"OWES","OVERPAID")))) -> OUTSTANDING
A23: 8 | B23: {=IFERROR(IF(INDEX(Transactions!$F$8:$F$3006,MATCH(0,COUNTIF($B$11:B22,Transactions!$F$8:$F$3006),0))="","",INDEX(Transactions!$F$8:$F$3006,MATCH(0,COUNTIF($B$11:B22,Transactions!$F$8:$F$3006),0))),"")} -> Kai | C23: =IF(B23="","",SUMIF(Transactions!$F$8:$F$3006,B23,Transactions!$H$8:$H$3006)) -> 0 | D23: =IF(B23="","",SUMIF(Transactions!$F$8:$F$3006,B23,Transactions!$N$8:$N$3006)) -> 200 | E23: =IF(B23="","",SUMIF(Transactions!$F$8:$F$3006,B23,Transactions!$O$8:$O$3006)) -> 0 | F23: =IF(B23="","",SUMIF(Transactions!$F$8:$F$3006,B23,Transactions!$R$8:$R$3006)) -> 0 | G23: =IF(B23="","",(C23+F23)-(D23+E23+SUMIF(Transactions!$F$8:$F$3006,B23,Transactions!$Q$8:$Q$3006))) -> -200 | H23: =IF(B23="","",IF(G23>0,"OUTSTANDING",IF(G23=0,"SETTLED",IF(SUMIF(Transactions!$F$8:$F$3006,B23,Transactions!$Q$8:$Q$3006)>SUMIF(Transactions!$F$8:$F$3006,B23,Transactions!$R$8:$R$3006),"OWES","OVERPAID")))) -> OVERPAID
A24: 9 | B24: {=IFERROR(IF(INDEX(Transactions!$F$8:$F$3006,MATCH(0,COUNTIF($B$11:B23,Transactions!$F$8:$F$3006),0))="","",INDEX(Transactions!$F$8:$F$3006,MATCH(0,COUNTIF($B$11:B23,Transactions!$F$8:$F$3006),0))),"")} -> Leo | C24: =IF(B24="","",SUMIF(Transactions!$F$8:$F$3006,B24,Transactions!$H$8:$H$3006)) -> 1000 | D24: =IF(B24="","",SUMIF(Transactions!$F$8:$F$3006,B24,Transactions!$N$8:$N$3006)) -> 500 | E24: =IF(B24="","",SUMIF(Transactions!$F$8:$F$3006,B24,Transactions!$O$8:$O$3006)) -> 0 | F24: =IF(B24="","",SUMIF(Transactions!$F$8:$F$3006,B24,Transactions!$R$8:$R$3006)) -> 0 | G24: =IF(B24="","",(C24+F24)-(D24+E24+SUMIF(Transactions!$F$8:$F$3006,B24,Transactions!$Q$8:$Q$3006))) -> 500 | H24: =IF(B24="","",IF(G24>0,"OUTSTANDING",IF(G24=0,"SETTLED",IF(SUMIF(Transactions!$F$8:$F$3006,B24,Transactions!$Q$8:$Q$3006)>SUMIF(Transactions!$F$8:$F$3006,B24,Transactions!$R$8:$R$3006),"OWES","OVERPAID")))) -> OUTSTANDING
A25: 10 | B25: {=IFERROR(IF(INDEX(Transactions!$F$8:$F$3006,MATCH(0,COUNTIF($B$11:B24,Transactions!$F$8:$F$3006),0))="","",INDEX(Transactions!$F$8:$F$3006,MATCH(0,COUNTIF($B$11:B24,Transactions!$F$8:$F$3006),0))),"")} -> Max | C25: =IF(B25="","",SUMIF(Transactions!$F$8:$F$3006,B25,Transactions!$H$8:$H$3006)) -> 0 | D25: =IF(B25="","",SUMIF(Transactions!$F$8:$F$3006,B25,Transactions!$N$8:$N$3006)) -> 300 | E25: =IF(B25="","",SUMIF(Transactions!$F$8:$F$3006,B25,Transactions!$O$8:$O$3006)) -> 0 | F25: =IF(B25="","",SUMIF(Transactions!$F$8:$F$3006,B25,Transactions!$R$8:$R$3006)) -> 0 | G25: =IF(B25="","",(C25+F25)-(D25+E25+SUMIF(Transactions!$F$8:$F$3006,B25,Transactions!$Q$8:$Q$3006))) -> -300 | H25: =IF(B25="","",IF(G25>0,"OUTSTANDING",IF(G25=0,"SETTLED",IF(SUMIF(Transactions!$F$8:$F$3006,B25,Transactions!$Q$8:$Q$3006)>SUMIF(Transactions!$F$8:$F$3006,B25,Transactions!$R$8:$R$3006),"OWES","OVERPAID")))) -> OVERPAID
A26: 11 | B26: {=IFERROR(IF(INDEX(Transactions!$F$8:$F$3006,MATCH(0,COUNTIF($B$11:B25,Transactions!$F$8:$F$3006),0))="","",INDEX(Transactions!$F$8:$F$3006,MATCH(0,COUNTIF($B$11:B25,Transactions!$F$8:$F$3006),0))),"")} -> Neo | C26: =IF(B26="","",SUMIF(Transactions!$F$8:$F$3006,B26,Transactions!$H$8:$H$3006)) -> 0 | D26: =IF(B26="","",SUMIF(Transactions!$F$8:$F$3006,B26,Transactions!$N$8:$N$3006)) -> 0 | E26: =IF(B26="","",SUMIF(Transactions!$F$8:$F$3006,B26,Transactions!$O$8:$O$3006)) -> 0 | F26: =IF(B26="","",SUMIF(Transactions!$F$8:$F$3006,B26,Transactions!$R$8:$R$3006)) -> 0 | G26: =IF(B26="","",(C26+F26)-(D26+E26+SUMIF(Transactions!$F$8:$F$3006,B26,Transactions!$Q$8:$Q$3006))) -> -600 | H26: =IF(B26="","",IF(G26>0,"OUTSTANDING",IF(G26=0,"SETTLED",IF(SUMIF(Transactions!$F$8:$F$3006,B26,Transactions!$Q$8:$Q$3006)>SUMIF(Transactions!$F$8:$F$3006,B26,Transactions!$R$8:$R$3006),"OWES","OVERPAID")))) -> OWES
A27: 12 | B27: {=IFERROR(IF(INDEX(Transactions!$F$8:$F$3006,MATCH(0,COUNTIF($B$11:B26,Transactions!$F$8:$F$3006),0))="","",INDEX(Transactions!$F$8:$F$3006,MATCH(0,COUNTIF($B$11:B26,Transactions!$F$8:$F$3006),0))),"")} -> Oli | C27: =IF(B27="","",SUMIF(Transactions!$F$8:$F$3006,B27,Transactions!$H$8:$H$3006)) -> 1000 | D27: =IF(B27="","",SUMIF(Transactions!$F$8:$F$3006,B27,Transactions!$N$8:$N$3006)) -> 0 | E27: =IF(B27="","",SUMIF(Transactions!$F$8:$F$3006,B27,Transactions!$O$8:$O$3006)) -> 0 | F27: =IF(B27="","",SUMIF(Transactions!$F$8:$F$3006,B27,Transactions!$R$8:$R$3006)) -> 0 | G27: =IF(B27="","",(C27+F27)-(D27+E27+SUMIF(Transactions!$F$8:$F$3006,B27,Transactions!$Q$8:$Q$3006))) -> 1000 | H27: =IF(B27="","",IF(G27>0,"OUTSTANDING",IF(G27=0,"SETTLED",IF(SUMIF(Transactions!$F$8:$F$3006,B27,Transactions!$Q$8:$Q$3006)>SUMIF(Transactions!$F$8:$F$3006,B27,Transactions!$R$8:$R$3006),"OWES","OVERPAID")))) -> OUTSTANDING
... A3015: 3000 | B3015: {=IFERROR(IF(INDEX(Transactions!$F$8:$F$3006,MATCH(0,COUNTIF($B$11:B3014,Transactions!$F$8:$F$3006),0))="","",INDEX(Transactions!$F$8:$F$3006,MATCH(0,COUNTIF($B$11:B3014,Transactions!$F$8:$F$3006),0))),"")} | C3015: =IF(B3015="","",SUMIF(Transactions!$F$8:$F$3006,B3015,Transactions!$H$8:$H$3006)) | D3015: =IF(B3015="","",SUMIF(Transactions!$F$8:$F$3006,B3015,Transactions!$N$8:$N$3006)) | E3015: =IF(B3015="","",SUMIF(Transactions!$F$8:$F$3006,B3015,Transactions!$O$8:$O$3006)) | F3015: =IF(B3015="","",SUMIF(Transactions!$F$8:$F$3006,B3015,Transactions!$R$8:$R$3006)) | G3015: =IF(B3015="","",(C3015+F3015)-(D3015+E3015+SUMIF(Transactions!$F$8:$F$3006,B3015,Transactions!$Q$8:$Q$3006))) | H3015: =IF(B3015="","",IF(G3015>0,"OUTSTANDING",IF(G3015=0,"SETTLED",IF(SUMIF(Transactions!$F$8:$F$3006,B3015,Transactions!$Q$8:$Q$3006)>SUMIF(Transactions!$F$8:$F$3006,B3015,Transactions!$R$8:$R$3006),"OWES","OVERPAID"))))

Sheet Guide
A1: PETTY CASH BOOK — REFERENCE GUIDE
A2: Discovery Dunes Site | Complete guide to using this workbook correctly
B4: 1. WHAT IS PETTY CASH?
B5: Purpose | C5: Petty cash is a small reserve of money kept on-site to cover minor day-to-day expenses (fuel, food, materials, small services) without going through the main accounts process. This workbook tracks every dirham in and out.
B6: How it flows | C6: Company sends cash to site (replenishment) → Site manager advances money to site team members → Site Team Members spend and return receipts or leftover cash → Manager records everything → Outstanding Advances sheet shows who owes what at all times.
B7: Two sheets | C7: PETTY CASH BOOK = every individual transaction. OUTSTANDING ADVANCES = one summarised line per site team member showing their running balance. The Outstanding sheet updates automatically — do not edit it directly.
B9: 2. PETTY CASH BOOK — COLUMN GUIDE
B10: CASH-IN (Replenishments) — Columns A, B, C
B11: A — Date | C11: Date the replenishment cash was received from Head Office or management.
B12: B — Description | C12: Brief note on the source of funds. e.g. 'Received from HO', 'Balance c/d from previous month'.
B13: C — Amount Received | C13: The actual cash amount received. This adds to the total cash-in and feeds the Closing Balance KPI.
B15: VOUCHER / ADVANCE DETAILS — Columns D, E, F, G, H
B16: D — Ref. No. | C16: Voucher reference number. Use a consistent format e.g. V-001, V-002. Each advance or transaction should have a unique reference for traceability.
B17: E — Voucher Date | C17: The date the advance was given or the transaction occurred. May differ from the Cash-In date in column A.
B18: F — Payee / Site Team Member | C18: Name of the person who received the advance or submitted the bill. This name is used by the Outstanding Advances sheet to group all transactions for that person. Spelling must be consistent — 'Ahmed' and 'AHMED' are treated as two different people.
B19: G — Purpose | C19: Nature of the transaction. Use: Advance / Returned / Reimbursement / Balance.
B20: H — Amount Advanced | C20: Cash given to the site team member as an advance. This increases what the site team member owes the company.
B22: EXPENSE BREAKDOWN — Columns I, J, K, L, M
B23: I — Fuel | C23: Amount spent on fuel, verified by receipt or bill.
B24: J — Service / Labour | C24: Amount spent on labour or services, verified by receipt.
B25: K — Materials | C25: Amount spent on materials or supplies, verified by receipt.
B26: L — Food Allowance | C26: Amount spent on food or meal allowances, verified by receipt.
B27: M — Others | C27: Any other miscellaneous expense not covered by the above categories.
B28: O — Actual Expense (auto) | C28: Auto-calculated: sum of columns I+J+K+L+M. Do not edit. Represents total proven spending by the site team member — reduces their outstanding balance.
B30: SETTLEMENT — Columns N, P, Q, R, S
B31: N — Balance Returned | C31: Cash physically handed back by the site team member. If X received 500 and spent 200, they return 300 in cash → enter 300 here.
B32: P — Variance (auto) | C32: Auto-calculated: Amount Advanced (H) minus Actual Expense (O). Shows the unaccounted gap. Should be zero when a transaction is fully settled.
B33: Q — Reimb. Amount | C33: The bill amount the site team member is submitting for reimbursement. e.g. Site Team Member paid 500 from their own pocket for materials → enter 500.
B34: R — Reimb. Paid | C34: The actual cash YOU paid out to the site team member for the reimbursement. This may be less than Q if you deduct an outstanding advance. e.g. Site Team Member submits 500 bill but owes 300 advance → you pay 200, enter 200 here.
B35: S — Change Due Back (auto) | C35: Auto-calculated: if Reimb. Paid (R) is more than the bill (Q), the excess is change the site team member must return. e.g. No change available, you pay 1000 for a 500 bill → 500 change is automatically tracked as outstanding on that site team member.
B37: 3. OUTSTANDING ADVANCES — COLUMN GUIDE
B38: B — Site Team Member / Payee | C38: Auto-populated from the Petty Cash Book. Every unique name in column F of PCB automatically gets a row here. Do not type names manually in this column.
B39: C — Total Advanced | C39: Sum of all advances (column H) given to this site team member across all entries.
B40: D — Total Returned | C40: Sum of all cash returned (column N) by this site team member.
B41: E — Actual Expense | C41: Sum of all proven expenses (column O) by this site team member, supported by receipts.
B42: F — Reimb. Paid | C42: Sum of all reimbursement payments (column R) made to this site team member.
B43: G — Net Outstanding | C43: The single most important number. Formula: (Advanced + Reimb Paid) − (Returned + Actual Expense + Bills Submitted). Positive = site team member owes company. Negative = company owes site team member.
B44: H — Status | C44: Auto-assigned based on Net Outstanding. See Section 5 for full status definitions.
B46: 4. HOW THE BALANCE IS CALCULATED
B47: The formula | C47: Net Outstanding = (Amount Advanced + Reimb. Paid) − (Cash Returned + Actual Expense + Bills Submitted)
...
